[2023-12-15T00:26:43.895+0000] {taskinstance.py:1159} INFO - Dependencies all met for dep_context=non-requeueable deps ti=<TaskInstance: open_fda.extract scheduled__2023-12-14T00:00:00+00:00 [queued]>
[2023-12-15T00:26:43.903+0000] {taskinstance.py:1159} INFO - Dependencies all met for dep_context=requeueable deps ti=<TaskInstance: open_fda.extract scheduled__2023-12-14T00:00:00+00:00 [queued]>
[2023-12-15T00:26:43.903+0000] {taskinstance.py:1361} INFO - Starting attempt 1 of 1
[2023-12-15T00:26:43.916+0000] {taskinstance.py:1382} INFO - Executing <Task(PythonOperator): extract> on 2023-12-14 00:00:00+00:00
[2023-12-15T00:26:43.922+0000] {standard_task_runner.py:57} INFO - Started process 927 to run task
[2023-12-15T00:26:43.928+0000] {standard_task_runner.py:84} INFO - Running: ['***', 'tasks', 'run', 'open_fda', 'extract', 'scheduled__2023-12-14T00:00:00+00:00', '--job-id', '15', '--raw', '--subdir', 'DAGS_FOLDER/outcome_dag.py', '--cfg-path', '/tmp/tmpn7h1acdq']
[2023-12-15T00:26:43.930+0000] {standard_task_runner.py:85} INFO - Job 15: Subtask extract
[2023-12-15T00:26:43.973+0000] {task_command.py:416} INFO - Running <TaskInstance: open_fda.extract scheduled__2023-12-14T00:00:00+00:00 [running]> on host 3a11139d188c
[2023-12-15T00:26:44.044+0000] {taskinstance.py:1662} INFO - Exporting env vars: AIRFLOW_CTX_DAG_OWNER='***' AIRFLOW_CTX_DAG_ID='open_fda' AIRFLOW_CTX_TASK_ID='extract' AIRFLOW_CTX_EXECUTION_DATE='2023-12-14T00:00:00+00:00' AIRFLOW_CTX_TRY_NUMBER='1' AIRFLOW_CTX_DAG_RUN_ID='scheduled__2023-12-14T00:00:00+00:00'
[2023-12-15T00:26:44.070+0000] {taskinstance.py:1937} ERROR - Task failed with exception
Traceback (most recent call last):
  File "/home/airflow/.local/lib/python3.8/site-packages/urllib3/connection.py", line 174, in _new_conn
    conn = connection.create_connection(
  File "/home/airflow/.local/lib/python3.8/site-packages/urllib3/util/connection.py", line 72, in create_connection
    for res in socket.getaddrinfo(host, port, family, socket.SOCK_STREAM):
  File "/usr/local/lib/python3.8/socket.py", line 918, in getaddrinfo
    for res in _socket.getaddrinfo(host, port, family, type, proto, flags):
socket.gaierror: [Errno -2] Name or service not known

During handling of the above exception, another exception occurred:

Traceback (most recent call last):
  File "/home/airflow/.local/lib/python3.8/site-packages/urllib3/connectionpool.py", line 715, in urlopen
    httplib_response = self._make_request(
  File "/home/airflow/.local/lib/python3.8/site-packages/urllib3/connectionpool.py", line 404, in _make_request
    self._validate_conn(conn)
  File "/home/airflow/.local/lib/python3.8/site-packages/urllib3/connectionpool.py", line 1058, in _validate_conn
    conn.connect()
  File "/home/airflow/.local/lib/python3.8/site-packages/urllib3/connection.py", line 363, in connect
    self.sock = conn = self._new_conn()
  File "/home/airflow/.local/lib/python3.8/site-packages/urllib3/connection.py", line 186, in _new_conn
    raise NewConnectionError(
urllib3.exceptions.NewConnectionError: <urllib3.connection.HTTPSConnection object at 0xffff97e30b80>: Failed to establish a new connection: [Errno -2] Name or service not known

During handling of the above exception, another exception occurred:

Traceback (most recent call last):
  File "/home/airflow/.local/lib/python3.8/site-packages/requests/adapters.py", line 486, in send
    resp = conn.urlopen(
  File "/home/airflow/.local/lib/python3.8/site-packages/urllib3/connectionpool.py", line 799, in urlopen
    retries = retries.increment(
  File "/home/airflow/.local/lib/python3.8/site-packages/urllib3/util/retry.py", line 592, in increment
    raise MaxRetryError(_pool, url, error or ResponseError(cause))
urllib3.exceptions.MaxRetryError: HTTPSConnectionPool(host='api.fda.gov', port=443): Max retries exceeded with url: /device/recall.json?search=root_cause_description.exact%3A%27Device+Design%27&limit=1000 (Caused by NewConnectionError('<urllib3.connection.HTTPSConnection object at 0xffff97e30b80>: Failed to establish a new connection: [Errno -2] Name or service not known'))

During handling of the above exception, another exception occurred:

Traceback (most recent call last):
  File "/home/airflow/.local/lib/python3.8/site-packages/airflow/operators/python.py", line 192, in execute
    return_value = self.execute_callable()
  File "/home/airflow/.local/lib/python3.8/site-packages/airflow/operators/python.py", line 209, in execute_callable
    return self.python_callable(*self.op_args, **self.op_kwargs)
  File "/opt/airflow/dags/etl/data_ingestion.py", line 16, in get_data
    response = requests.get(api_endpoint, params=params)
  File "/home/airflow/.local/lib/python3.8/site-packages/requests/api.py", line 73, in get
    return request("get", url, params=params, **kwargs)
  File "/home/airflow/.local/lib/python3.8/site-packages/requests/api.py", line 59, in request
    return session.request(method=method, url=url, **kwargs)
  File "/home/airflow/.local/lib/python3.8/site-packages/requests/sessions.py", line 589, in request
    resp = self.send(prep, **send_kwargs)
  File "/home/airflow/.local/lib/python3.8/site-packages/requests/sessions.py", line 703, in send
    r = adapter.send(request, **kwargs)
  File "/home/airflow/.local/lib/python3.8/site-packages/requests/adapters.py", line 519, in send
    raise ConnectionError(e, request=request)
requests.exceptions.ConnectionError: HTTPSConnectionPool(host='api.fda.gov', port=443): Max retries exceeded with url: /device/recall.json?search=root_cause_description.exact%3A%27Device+Design%27&limit=1000 (Caused by NewConnectionError('<urllib3.connection.HTTPSConnection object at 0xffff97e30b80>: Failed to establish a new connection: [Errno -2] Name or service not known'))
[2023-12-15T00:26:44.104+0000] {taskinstance.py:1400} INFO - Marking task as FAILED. dag_id=open_fda, task_id=extract, execution_date=20231214T000000, start_date=20231215T002643, end_date=20231215T002644
[2023-12-15T00:26:44.128+0000] {standard_task_runner.py:104} ERROR - Failed to execute job 15 for task extract (HTTPSConnectionPool(host='api.fda.gov', port=443): Max retries exceeded with url: /device/recall.json?search=root_cause_description.exact%3A%27Device+Design%27&limit=1000 (Caused by NewConnectionError('<urllib3.connection.HTTPSConnection object at 0xffff97e30b80>: Failed to establish a new connection: [Errno -2] Name or service not known')); 927)
[2023-12-15T00:26:44.181+0000] {local_task_job_runner.py:228} INFO - Task exited with return code 1
[2023-12-15T00:26:44.220+0000] {taskinstance.py:2778} INFO - 0 downstream tasks scheduled from follow-on schedule check
