[2023-12-14T11:00:59.770+0000] {taskinstance.py:1159} INFO - Dependencies all met for dep_context=non-requeueable deps ti=<TaskInstance: open_fda.transform manual__2023-12-14T11:00:30.347844+00:00 [queued]>
[2023-12-14T11:00:59.773+0000] {taskinstance.py:1159} INFO - Dependencies all met for dep_context=requeueable deps ti=<TaskInstance: open_fda.transform manual__2023-12-14T11:00:30.347844+00:00 [queued]>
[2023-12-14T11:00:59.773+0000] {taskinstance.py:1361} INFO - Starting attempt 1 of 1
[2023-12-14T11:00:59.778+0000] {taskinstance.py:1382} INFO - Executing <Task(PythonOperator): transform> on 2023-12-14 11:00:30.347844+00:00
[2023-12-14T11:00:59.782+0000] {standard_task_runner.py:57} INFO - Started process 126 to run task
[2023-12-14T11:00:59.784+0000] {standard_task_runner.py:84} INFO - Running: ['***', 'tasks', 'run', 'open_fda', 'transform', 'manual__2023-12-14T11:00:30.347844+00:00', '--job-id', '6', '--raw', '--subdir', 'DAGS_FOLDER/outcome_dag.py', '--cfg-path', '/tmp/tmppqfeq3xt']
[2023-12-14T11:00:59.785+0000] {standard_task_runner.py:85} INFO - Job 6: Subtask transform
[2023-12-14T11:00:59.816+0000] {task_command.py:416} INFO - Running <TaskInstance: open_fda.transform manual__2023-12-14T11:00:30.347844+00:00 [running]> on host a8e3069b13ec
[2023-12-14T11:00:59.852+0000] {taskinstance.py:1662} INFO - Exporting env vars: AIRFLOW_CTX_DAG_OWNER='***' AIRFLOW_CTX_DAG_ID='open_fda' AIRFLOW_CTX_TASK_ID='transform' AIRFLOW_CTX_EXECUTION_DATE='2023-12-14T11:00:30.347844+00:00' AIRFLOW_CTX_TRY_NUMBER='1' AIRFLOW_CTX_DAG_RUN_ID='manual__2023-12-14T11:00:30.347844+00:00'
[2023-12-14T11:00:59.853+0000] {taskinstance.py:1937} ERROR - Task failed with exception
Traceback (most recent call last):
  File "/home/airflow/.local/lib/python3.8/site-packages/airflow/operators/python.py", line 192, in execute
    return_value = self.execute_callable()
  File "/home/airflow/.local/lib/python3.8/site-packages/airflow/operators/python.py", line 209, in execute_callable
    return self.python_callable(*self.op_args, **self.op_kwargs)
  File "/opt/airflow/dags/etl/transformation.py", line 7, in transform_data
    create_table()
  File "/opt/airflow/dags/db/table_creation.py", line 14, in create_table
    conn = psycopg2.connect(
  File "/home/airflow/.local/lib/python3.8/site-packages/psycopg2/__init__.py", line 122, in connect
    conn = _connect(dsn, connection_factory=connection_factory, **kwasync)
psycopg2.OperationalError: connection to server on socket "/var/run/postgresql/.s.PGSQL.5439" failed: No such file or directory
	Is the server running locally and accepting connections on that socket?

[2023-12-14T11:00:59.859+0000] {taskinstance.py:1400} INFO - Marking task as FAILED. dag_id=open_fda, task_id=transform, execution_date=20231214T110030, start_date=20231214T110059, end_date=20231214T110059
[2023-12-14T11:00:59.863+0000] {standard_task_runner.py:104} ERROR - Failed to execute job 6 for task transform (connection to server on socket "/var/run/postgresql/.s.PGSQL.5439" failed: No such file or directory
	Is the server running locally and accepting connections on that socket?
; 126)
[2023-12-14T11:00:59.876+0000] {local_task_job_runner.py:228} INFO - Task exited with return code 1
[2023-12-14T11:00:59.888+0000] {taskinstance.py:2778} INFO - 0 downstream tasks scheduled from follow-on schedule check
