[2023-12-14T22:36:58.896+0000] {taskinstance.py:1159} INFO - Dependencies all met for dep_context=non-requeueable deps ti=<TaskInstance: open_fda.load manual__2023-12-14T22:35:58.336762+00:00 [queued]>
[2023-12-14T22:36:58.900+0000] {taskinstance.py:1159} INFO - Dependencies all met for dep_context=requeueable deps ti=<TaskInstance: open_fda.load manual__2023-12-14T22:35:58.336762+00:00 [queued]>
[2023-12-14T22:36:58.900+0000] {taskinstance.py:1361} INFO - Starting attempt 1 of 1
[2023-12-14T22:36:58.905+0000] {taskinstance.py:1382} INFO - Executing <Task(PythonOperator): load> on 2023-12-14 22:35:58.336762+00:00
[2023-12-14T22:36:58.910+0000] {standard_task_runner.py:57} INFO - Started process 117 to run task
[2023-12-14T22:36:58.914+0000] {standard_task_runner.py:84} INFO - Running: ['***', 'tasks', 'run', 'open_fda', 'load', 'manual__2023-12-14T22:35:58.336762+00:00', '--job-id', '11', '--raw', '--subdir', 'DAGS_FOLDER/outcome_dag.py', '--cfg-path', '/tmp/tmpf3ywi5if']
[2023-12-14T22:36:58.915+0000] {standard_task_runner.py:85} INFO - Job 11: Subtask load
[2023-12-14T22:36:58.949+0000] {task_command.py:416} INFO - Running <TaskInstance: open_fda.load manual__2023-12-14T22:35:58.336762+00:00 [running]> on host 3a11139d188c
[2023-12-14T22:36:59.000+0000] {taskinstance.py:1662} INFO - Exporting env vars: AIRFLOW_CTX_DAG_OWNER='***' AIRFLOW_CTX_DAG_ID='open_fda' AIRFLOW_CTX_TASK_ID='load' AIRFLOW_CTX_EXECUTION_DATE='2023-12-14T22:35:58.336762+00:00' AIRFLOW_CTX_TRY_NUMBER='1' AIRFLOW_CTX_DAG_RUN_ID='manual__2023-12-14T22:35:58.336762+00:00'
[2023-12-14T22:36:59.003+0000] {warnings.py:109} WARNING - /home/***/.local/lib/python3.8/site-packages/***/utils/context.py:314: AirflowContextDeprecationWarning: Accessing 'execution_date' from the template is deprecated and will be removed in a future version. Please use 'data_interval_start' or 'logical_date' instead.
  warnings.warn(_create_deprecation_warning(k, replacements))

[2023-12-14T22:57:45.384+0000] {taskinstance.py:1937} ERROR - Task failed with exception
Traceback (most recent call last):
  File "/home/airflow/.local/lib/python3.8/site-packages/sqlalchemy/engine/base.py", line 1910, in _execute_context
    self.dialect.do_execute(
  File "/home/airflow/.local/lib/python3.8/site-packages/sqlalchemy/engine/default.py", line 736, in do_execute
    cursor.execute(statement, parameters)
psycopg2.errors.InternalError_: could not open relation with OID 106893


The above exception was the direct cause of the following exception:

Traceback (most recent call last):
  File "/home/airflow/.local/lib/python3.8/site-packages/airflow/operators/python.py", line 192, in execute
    return_value = self.execute_callable()
  File "/home/airflow/.local/lib/python3.8/site-packages/airflow/operators/python.py", line 209, in execute_callable
    return self.python_callable(*self.op_args, **self.op_kwargs)
  File "/opt/airflow/dags/etl/load.py", line 17, in load_data
    df.to_sql('recall', engine, index=False,if_exists='replace')
  File "/home/airflow/.local/lib/python3.8/site-packages/pandas/core/generic.py", line 2878, in to_sql
    return sql.to_sql(
  File "/home/airflow/.local/lib/python3.8/site-packages/pandas/io/sql.py", line 769, in to_sql
    return pandas_sql.to_sql(
  File "/home/airflow/.local/lib/python3.8/site-packages/pandas/io/sql.py", line 1910, in to_sql
    table = self.prep_table(
  File "/home/airflow/.local/lib/python3.8/site-packages/pandas/io/sql.py", line 1814, in prep_table
    table.create()
  File "/home/airflow/.local/lib/python3.8/site-packages/pandas/io/sql.py", line 907, in create
    self.pd_sql.drop_table(self.name, self.schema)
  File "/home/airflow/.local/lib/python3.8/site-packages/pandas/io/sql.py", line 1963, in drop_table
    self.get_table(table_name, schema).drop(bind=self.con)
  File "/home/airflow/.local/lib/python3.8/site-packages/sqlalchemy/sql/schema.py", line 979, in drop
    bind._run_ddl_visitor(ddl.SchemaDropper, self, checkfirst=checkfirst)
  File "/home/airflow/.local/lib/python3.8/site-packages/sqlalchemy/engine/base.py", line 2221, in _run_ddl_visitor
    visitorcallable(self.dialect, self, **kwargs).traverse_single(element)
  File "/home/airflow/.local/lib/python3.8/site-packages/sqlalchemy/sql/visitors.py", line 524, in traverse_single
    return meth(obj, **kw)
  File "/home/airflow/.local/lib/python3.8/site-packages/sqlalchemy/sql/ddl.py", line 1106, in visit_table
    self.connection.execute(DropTable(table))
  File "/home/airflow/.local/lib/python3.8/site-packages/sqlalchemy/engine/base.py", line 1385, in execute
    return meth(self, multiparams, params, _EMPTY_EXECUTION_OPTS)
  File "/home/airflow/.local/lib/python3.8/site-packages/sqlalchemy/sql/ddl.py", line 80, in _execute_on_connection
    return connection._execute_ddl(
  File "/home/airflow/.local/lib/python3.8/site-packages/sqlalchemy/engine/base.py", line 1477, in _execute_ddl
    ret = self._execute_context(
  File "/home/airflow/.local/lib/python3.8/site-packages/sqlalchemy/engine/base.py", line 1953, in _execute_context
    self._handle_dbapi_exception(
  File "/home/airflow/.local/lib/python3.8/site-packages/sqlalchemy/engine/base.py", line 2134, in _handle_dbapi_exception
    util.raise_(
  File "/home/airflow/.local/lib/python3.8/site-packages/sqlalchemy/util/compat.py", line 211, in raise_
    raise exception
  File "/home/airflow/.local/lib/python3.8/site-packages/sqlalchemy/engine/base.py", line 1910, in _execute_context
    self.dialect.do_execute(
  File "/home/airflow/.local/lib/python3.8/site-packages/sqlalchemy/engine/default.py", line 736, in do_execute
    cursor.execute(statement, parameters)
sqlalchemy.exc.InternalError: (psycopg2.errors.InternalError_) could not open relation with OID 106893

[SQL: 
DROP TABLE recall]
(Background on this error at: https://sqlalche.me/e/14/2j85)
[2023-12-14T22:57:45.447+0000] {taskinstance.py:1400} INFO - Marking task as FAILED. dag_id=open_fda, task_id=load, execution_date=20231214T223558, start_date=20231214T223658, end_date=20231214T225745
[2023-12-14T22:57:45.470+0000] {standard_task_runner.py:104} ERROR - Failed to execute job 11 for task load ((psycopg2.errors.InternalError_) could not open relation with OID 106893

[SQL: 
DROP TABLE recall]
(Background on this error at: https://sqlalche.me/e/14/2j85); 117)
[2023-12-14T22:57:45.495+0000] {local_task_job_runner.py:228} INFO - Task exited with return code 1
[2023-12-14T22:57:45.514+0000] {taskinstance.py:2778} INFO - 0 downstream tasks scheduled from follow-on schedule check
