[2023-12-14T11:04:53.263+0000] {taskinstance.py:1159} INFO - Dependencies all met for dep_context=non-requeueable deps ti=<TaskInstance: open_fda.transform manual__2023-12-14T11:04:22.706170+00:00 [queued]>
[2023-12-14T11:04:53.266+0000] {taskinstance.py:1159} INFO - Dependencies all met for dep_context=requeueable deps ti=<TaskInstance: open_fda.transform manual__2023-12-14T11:04:22.706170+00:00 [queued]>
[2023-12-14T11:04:53.266+0000] {taskinstance.py:1361} INFO - Starting attempt 1 of 1
[2023-12-14T11:04:53.271+0000] {taskinstance.py:1382} INFO - Executing <Task(PythonOperator): transform> on 2023-12-14 11:04:22.706170+00:00
[2023-12-14T11:04:53.274+0000] {standard_task_runner.py:57} INFO - Started process 73 to run task
[2023-12-14T11:04:53.277+0000] {standard_task_runner.py:84} INFO - Running: ['***', 'tasks', 'run', 'open_fda', 'transform', 'manual__2023-12-14T11:04:22.706170+00:00', '--job-id', '4', '--raw', '--subdir', 'DAGS_FOLDER/outcome_dag.py', '--cfg-path', '/tmp/tmpk7vt7f4r']
[2023-12-14T11:04:53.278+0000] {standard_task_runner.py:85} INFO - Job 4: Subtask transform
[2023-12-14T11:04:53.306+0000] {task_command.py:416} INFO - Running <TaskInstance: open_fda.transform manual__2023-12-14T11:04:22.706170+00:00 [running]> on host d3a1e936d772
[2023-12-14T11:04:53.342+0000] {taskinstance.py:1662} INFO - Exporting env vars: AIRFLOW_CTX_DAG_OWNER='***' AIRFLOW_CTX_DAG_ID='open_fda' AIRFLOW_CTX_TASK_ID='transform' AIRFLOW_CTX_EXECUTION_DATE='2023-12-14T11:04:22.706170+00:00' AIRFLOW_CTX_TRY_NUMBER='1' AIRFLOW_CTX_DAG_RUN_ID='manual__2023-12-14T11:04:22.706170+00:00'
[2023-12-14T11:06:08.443+0000] {taskinstance.py:1937} ERROR - Task failed with exception
Traceback (most recent call last):
  File "/home/airflow/.local/lib/python3.8/site-packages/airflow/operators/python.py", line 192, in execute
    return_value = self.execute_callable()
  File "/home/airflow/.local/lib/python3.8/site-packages/airflow/operators/python.py", line 209, in execute_callable
    return self.python_callable(*self.op_args, **self.op_kwargs)
  File "/opt/airflow/dags/etl/transformation.py", line 7, in transform_data
    create_table()
  File "/opt/airflow/dags/db/table_creation.py", line 14, in create_table
    conn = psycopg2.connect(
  File "/home/airflow/.local/lib/python3.8/site-packages/psycopg2/__init__.py", line 122, in connect
    conn = _connect(dsn, connection_factory=connection_factory, **kwasync)
psycopg2.OperationalError: connection to server at "dc-db-instance.cvwmlpdligxr.us-east-2.rds.amazonaws.com" (3.135.147.62), port 5439 failed: Connection refused
	Is the server running on that host and accepting TCP/IP connections?

[2023-12-14T11:06:08.465+0000] {taskinstance.py:1400} INFO - Marking task as FAILED. dag_id=open_fda, task_id=transform, execution_date=20231214T110422, start_date=20231214T110453, end_date=20231214T110608
[2023-12-14T11:06:08.475+0000] {standard_task_runner.py:104} ERROR - Failed to execute job 4 for task transform (connection to server at "dc-db-instance.cvwmlpdligxr.us-east-2.rds.amazonaws.com" (3.135.147.62), port 5439 failed: Connection refused
	Is the server running on that host and accepting TCP/IP connections?
; 73)
[2023-12-14T11:06:08.508+0000] {local_task_job_runner.py:228} INFO - Task exited with return code 1
[2023-12-14T11:06:08.525+0000] {taskinstance.py:2778} INFO - 0 downstream tasks scheduled from follow-on schedule check
