[2023-12-14T19:09:42.374+0000] {taskinstance.py:1159} INFO - Dependencies all met for dep_context=non-requeueable deps ti=<TaskInstance: open_fda.load manual__2023-12-14T19:09:02.664876+00:00 [queued]>
[2023-12-14T19:09:42.377+0000] {taskinstance.py:1159} INFO - Dependencies all met for dep_context=requeueable deps ti=<TaskInstance: open_fda.load manual__2023-12-14T19:09:02.664876+00:00 [queued]>
[2023-12-14T19:09:42.377+0000] {taskinstance.py:1361} INFO - Starting attempt 1 of 1
[2023-12-14T19:09:42.382+0000] {taskinstance.py:1382} INFO - Executing <Task(PythonOperator): load> on 2023-12-14 19:09:02.664876+00:00
[2023-12-14T19:09:42.385+0000] {standard_task_runner.py:57} INFO - Started process 75 to run task
[2023-12-14T19:09:42.388+0000] {standard_task_runner.py:84} INFO - Running: ['***', 'tasks', 'run', 'open_fda', 'load', 'manual__2023-12-14T19:09:02.664876+00:00', '--job-id', '5', '--raw', '--subdir', 'DAGS_FOLDER/outcome_dag.py', '--cfg-path', '/tmp/tmp2qhmq499']
[2023-12-14T19:09:42.389+0000] {standard_task_runner.py:85} INFO - Job 5: Subtask load
[2023-12-14T19:09:42.417+0000] {task_command.py:416} INFO - Running <TaskInstance: open_fda.load manual__2023-12-14T19:09:02.664876+00:00 [running]> on host b9c035040597
[2023-12-14T19:09:42.456+0000] {taskinstance.py:1662} INFO - Exporting env vars: AIRFLOW_CTX_DAG_OWNER='***' AIRFLOW_CTX_DAG_ID='open_fda' AIRFLOW_CTX_TASK_ID='load' AIRFLOW_CTX_EXECUTION_DATE='2023-12-14T19:09:02.664876+00:00' AIRFLOW_CTX_TRY_NUMBER='1' AIRFLOW_CTX_DAG_RUN_ID='manual__2023-12-14T19:09:02.664876+00:00'
[2023-12-14T19:09:42.458+0000] {warnings.py:109} WARNING - /home/***/.local/lib/python3.8/site-packages/***/utils/context.py:314: AirflowContextDeprecationWarning: Accessing 'execution_date' from the template is deprecated and will be removed in a future version. Please use 'data_interval_start' or 'logical_date' instead.
  warnings.warn(_create_deprecation_warning(k, replacements))

[2023-12-14T19:34:10.123+0000] {local_task_job_runner.py:294} WARNING - State of this instance has been externally set to restarting. Terminating instance.
[2023-12-14T19:34:10.156+0000] {process_utils.py:131} INFO - Sending 15 to group 75. PIDs of all processes in the group: [75]
[2023-12-14T19:34:10.157+0000] {process_utils.py:86} INFO - Sending the signal 15 to group 75
[2023-12-14T19:34:10.184+0000] {taskinstance.py:1632} ERROR - Received SIGTERM. Terminating subprocesses.
[2023-12-14T19:34:10.332+0000] {taskinstance.py:1937} ERROR - Task failed with exception
Traceback (most recent call last):
  File "/home/airflow/.local/lib/python3.8/site-packages/airflow/operators/python.py", line 192, in execute
    return_value = self.execute_callable()
  File "/home/airflow/.local/lib/python3.8/site-packages/airflow/operators/python.py", line 209, in execute_callable
    return self.python_callable(*self.op_args, **self.op_kwargs)
  File "/opt/airflow/dags/etl/load.py", line 17, in load_data
    df.to_sql('recall', engine, index=False,if_exists='replace')
  File "/home/airflow/.local/lib/python3.8/site-packages/pandas/core/generic.py", line 2878, in to_sql
    return sql.to_sql(
  File "/home/airflow/.local/lib/python3.8/site-packages/pandas/io/sql.py", line 769, in to_sql
    return pandas_sql.to_sql(
  File "/home/airflow/.local/lib/python3.8/site-packages/pandas/io/sql.py", line 1920, in to_sql
    total_inserted = sql_engine.insert_records(
  File "/home/airflow/.local/lib/python3.8/site-packages/pandas/io/sql.py", line 1461, in insert_records
    return table.insert(chunksize=chunksize, method=method)
  File "/home/airflow/.local/lib/python3.8/site-packages/pandas/io/sql.py", line 1023, in insert
    num_inserted = exec_insert(conn, keys, chunk_iter)
  File "/home/airflow/.local/lib/python3.8/site-packages/pandas/io/sql.py", line 929, in _execute_insert
    result = conn.execute(self.table.insert(), data)
  File "/home/airflow/.local/lib/python3.8/site-packages/sqlalchemy/engine/base.py", line 1385, in execute
    return meth(self, multiparams, params, _EMPTY_EXECUTION_OPTS)
  File "/home/airflow/.local/lib/python3.8/site-packages/sqlalchemy/sql/elements.py", line 334, in _execute_on_connection
    return connection._execute_clauseelement(
  File "/home/airflow/.local/lib/python3.8/site-packages/sqlalchemy/engine/base.py", line 1577, in _execute_clauseelement
    ret = self._execute_context(
  File "/home/airflow/.local/lib/python3.8/site-packages/sqlalchemy/engine/base.py", line 1953, in _execute_context
    self._handle_dbapi_exception(
  File "/home/airflow/.local/lib/python3.8/site-packages/sqlalchemy/engine/base.py", line 2138, in _handle_dbapi_exception
    util.raise_(exc_info[1], with_traceback=exc_info[2])
  File "/home/airflow/.local/lib/python3.8/site-packages/sqlalchemy/util/compat.py", line 211, in raise_
    raise exception
  File "/home/airflow/.local/lib/python3.8/site-packages/sqlalchemy/engine/base.py", line 1890, in _execute_context
    self.dialect.do_executemany(
  File "/home/airflow/.local/lib/python3.8/site-packages/sqlalchemy/dialects/postgresql/psycopg2.py", line 1000, in do_executemany
    cursor.executemany(statement, parameters)
  File "/usr/local/lib/python3.8/encodings/utf_8.py", line 15, in decode
    def decode(input, errors='strict'):
  File "/home/airflow/.local/lib/python3.8/site-packages/airflow/models/taskinstance.py", line 1634, in signal_handler
    raise AirflowException("Task received SIGTERM signal")
airflow.exceptions.AirflowException: Task received SIGTERM signal
[2023-12-14T19:34:10.354+0000] {taskinstance.py:1400} INFO - Marking task as UP_FOR_RETRY. dag_id=open_fda, task_id=load, execution_date=20231214T190902, start_date=20231214T190942, end_date=20231214T193410
[2023-12-14T19:34:10.364+0000] {standard_task_runner.py:104} ERROR - Failed to execute job 5 for task load (Task received SIGTERM signal; 75)
[2023-12-14T19:34:10.394+0000] {process_utils.py:79} INFO - Process psutil.Process(pid=75, status='terminated', exitcode=1, started='19:09:41') (75) terminated with exit code 1
